<!DOCTYPE html>
<html lang="es">
<head>
    <meta charset="utf-8">
    <meta http-equiv="x-ua-compatible" content="ie=edge">
    <meta name="viewport" content="width=device-width, initial-scale=1.0">
    <title>Manejo de Excepciones en Código Asíncrono</title>

    <link rel="alternate" href="https://campusempresa.com/csharp/exceptions-async" hreflang="es" />
	<link rel="alternate" href="https://campusempresa.cat/csharp/exceptions-async" hreflang="ca" />
	<link rel="alternate" href="https://enterprisecampus.net/csharp/exceptions-async" hreflang="en" />
    
	<link href="https://cdn.jsdelivr.net/npm/bootstrap@5.3.3/dist/css/bootstrap.min.css" rel="stylesheet">
	<link rel="stylesheet" href="https://cdn.jsdelivr.net/npm/bootstrap-icons/font/bootstrap-icons.css">
	<link href="/css/site.css" rel="stylesheet">
	
    <script src="https://code.jquery.com/jquery-3.7.1.min.js"></script>
  	<script type="text/javascript" src="js/math_init.js"></script>
  	<script type="text/javascript" id="MathJax-script" src="https://cdn.jsdelivr.net/npm/mathjax@3/es5/startup.js"></script>
  	<script type="text/javascript" src="/js/cookie.js"></script>
  	<script type="text/javascript" src="/js/main.js"></script>
</head>

<body>
    <div id="content">
		<div id="header" class="container-xxl">
	<div class="row">
		<div class="col-8 p-0">
			<h1 class="m-0 p-0">
				<a href="/"><img src="/img/logo_header.png" style="visibility:hiddenxx;"></a>
			</h1>
		</div>
		<div class="col-4 p-0 text-end">
			<h2 id="main_title"><cite>Construyendo la sociedad de hoy y del mañana</cite></h2>
			<h3 id="main_subtitle"></h3>
		</div>
	</div>
</div>
<div class="container-xxl" style="margin-top: -1em;">
	<div class="row">
		<div class="col-12 p-0 m-0 text-end">
										<a href="https://enterprisecampus.net/csharp/exceptions-async" class="px-2">EN</a></b>
				|
				<b class="px-2">ES</b>
				|
				<a href="https://campusempresa.cat/csharp/exceptions-async" class="px-2">CA</a>
								</div>
	</div>
</div>
   <div class="top-bar container-fluid">
	<div class="container-xxl">
		<div class="row">
			<div class="col" id="left_menu">
				<a href="/objective">El Proyecto</a>
				<a href="/about">Sobre nosotros</a>
				<a href="/contribute">Contribuir</a>
				<a href="/donate">Donaciones</a>
				<a href="/licence">Licencia</a>
			</div>
		</div>
	</div>
   </div>

<div class="container-xxl" id="main_content">
	<div class="row">
		<div class="col-12 col-lg-8">
			<div id="nav1" class="navigation"></div>
			<div id="inner_content"><div class='row navigation'>
	<div class='col-4'>
					<a href='async-await'>&#x25C4;Async y Await</a>
			</div>
	<div class='col-4 text-center'>
		<a href="./" class="title">Manejo de Excepciones en Código Asíncrono</a>
	</div>
	<div class='col-4 text-end'>
					<a href='introduction-databases'>Introducción a las Bases de Datos &#x25BA;</a>
			</div>
</div>
<div class='content'></div><h1>Introducción</h1>
<div class='content'><p>Manejar excepciones en código asíncrono puede ser un desafío tanto para principiantes como para programadores avanzados. Esta sección te guiará a través de los conceptos básicos del manejo de excepciones en código asíncrono, progresando hacia técnicas más avanzadas y mejores prácticas.</p>
</div><h1>Conceptos Clave</h1>
<div class='content'><ul>
<li><strong>Programación Asíncrona</strong>: Ejecutar tareas en segundo plano sin bloquear el hilo principal.</li>
<li><strong>Excepciones</strong>: Errores que ocurren durante la ejecución de un programa.</li>
<li><strong>Manejo de Excepciones</strong>: Mecanismos para capturar y manejar errores de manera elegante.</li>
</ul>
</div><h1>Manejo Básico de Excepciones en Código Asíncrono</h1>
<div class='content'></div><h2>Usando `try-catch` con `async` y `await`</h2>
<div class='content'><p>Cuando trabajas con métodos asíncronos, puedes usar bloques <code>try-catch</code> para manejar excepciones tal como en el código síncrono.</p>
</div><div style='position:relative'><a class='copy_button' href='#' onclick='navigator.clipboard.writeText(decodeURIComponent(escape(atob("cHVibGljIGFzeW5jIFRhc2sgRXhhbXBsZU1ldGhvZEFzeW5jKCkKewogICAgdHJ5CiAgICB7CiAgICAgICAgYXdhaXQgVGFzay5SdW4oKCkgPT4geyB0aHJvdyBuZXcgSW52YWxpZE9wZXJhdGlvbkV4Y2VwdGlvbigiQW4gZXJyb3Igb2NjdXJyZWQuIik7IH0pOwogICAgfQogICAgY2F0Y2ggKEludmFsaWRPcGVyYXRpb25FeGNlcHRpb24gZXgpCiAgICB7CiAgICAgICAgQ29uc29sZS5Xcml0ZUxpbmUoJCJDYXVnaHQgYW4gZXhjZXB0aW9uOiB7ZXguTWVzc2FnZX0iKTsKICAgIH0KfQ=="))));alert("¡Copiado!");return false;'><i class='bi bi-copy'></i></a><pre class='code'>public async Task ExampleMethodAsync()
{
    try
    {
        await Task.Run(() =&gt; { throw new InvalidOperationException(&quot;An error occurred.&quot;); });
    }
    catch (InvalidOperationException ex)
    {
        Console.WriteLine($&quot;Caught an exception: {ex.Message}&quot;);
    }
}</pre></div><div class='content'><p>En este ejemplo:</p>
<ul>
<li><code>Task.Run</code> se usa para simular una operación asíncrona que lanza una excepción.</li>
<li>El bloque <code>try-catch</code> captura la <code>InvalidOperationException</code> y la maneja imprimiendo un mensaje en la consola.</li>
</ul>
</div><h1>Manejo de Excepciones en Múltiples Métodos Asíncronos</h1>
<div class='content'></div><h2>Propagación de Excepciones</h2>
<div class='content'><p>Las excepciones en métodos asíncronos pueden propagarse por la pila de llamadas. Puedes capturarlas en un nivel superior si es necesario.</p>
</div><div style='position:relative'><a class='copy_button' href='#' onclick='navigator.clipboard.writeText(decodeURIComponent(escape(atob("cHVibGljIGFzeW5jIFRhc2sgTWV0aG9kMUFzeW5jKCkKewogICAgYXdhaXQgTWV0aG9kMkFzeW5jKCk7Cn0KCnB1YmxpYyBhc3luYyBUYXNrIE1ldGhvZDJBc3luYygpCnsKICAgIHRocm93IG5ldyBJbnZhbGlkT3BlcmF0aW9uRXhjZXB0aW9uKCJBbiBlcnJvciBvY2N1cnJlZCBpbiBNZXRob2QyQXN5bmMuIik7Cn0KCnB1YmxpYyBhc3luYyBUYXNrIE1haW5NZXRob2RBc3luYygpCnsKICAgIHRyeQogICAgewogICAgICAgIGF3YWl0IE1ldGhvZDFBc3luYygpOwogICAgfQogICAgY2F0Y2ggKEludmFsaWRPcGVyYXRpb25FeGNlcHRpb24gZXgpCiAgICB7CiAgICAgICAgQ29uc29sZS5Xcml0ZUxpbmUoJCJDYXVnaHQgYW4gZXhjZXB0aW9uOiB7ZXguTWVzc2FnZX0iKTsKICAgIH0KfQ=="))));alert("¡Copiado!");return false;'><i class='bi bi-copy'></i></a><pre class='code'>public async Task Method1Async()
{
    await Method2Async();
}

public async Task Method2Async()
{
    throw new InvalidOperationException(&quot;An error occurred in Method2Async.&quot;);
}

public async Task MainMethodAsync()
{
    try
    {
        await Method1Async();
    }
    catch (InvalidOperationException ex)
    {
        Console.WriteLine($&quot;Caught an exception: {ex.Message}&quot;);
    }
}</pre></div><div class='content'><p>En este ejemplo:</p>
<ul>
<li><code>Method2Async</code> lanza una excepción.</li>
<li><code>Method1Async</code> llama a <code>Method2Async</code> pero no maneja la excepción.</li>
<li><code>MainMethodAsync</code> llama a <code>Method1Async</code> y captura la excepción propagada.</li>
</ul>
</div><h1>Manejo Avanzado de Excepciones</h1>
<div class='content'></div><h2>Usando `Task.WhenAll` con Manejo de Excepciones</h2>
<div class='content'><p>Cuando ejecutas múltiples tareas concurrentemente, puedes usar <code>Task.WhenAll</code> para esperar a que todas las tareas se completen y manejar las excepciones.</p>
</div><div style='position:relative'><a class='copy_button' href='#' onclick='navigator.clipboard.writeText(decodeURIComponent(escape(atob("cHVibGljIGFzeW5jIFRhc2sgUnVuTXVsdGlwbGVUYXNrc0FzeW5jKCkKewogICAgdmFyIHRhc2sxID0gVGFzay5SdW4oKCkgPT4geyB0aHJvdyBuZXcgSW52YWxpZE9wZXJhdGlvbkV4Y2VwdGlvbigiVGFzazEgZmFpbGVkLiIpOyB9KTsKICAgIHZhciB0YXNrMiA9IFRhc2suUnVuKCgpID0+IHsgdGhyb3cgbmV3IEludmFsaWRPcGVyYXRpb25FeGNlcHRpb24oIlRhc2syIGZhaWxlZC4iKTsgfSk7CgogICAgdHJ5CiAgICB7CiAgICAgICAgYXdhaXQgVGFzay5XaGVuQWxsKHRhc2sxLCB0YXNrMik7CiAgICB9CiAgICBjYXRjaCAoRXhjZXB0aW9uIGV4KQogICAgewogICAgICAgIGZvcmVhY2ggKHZhciBpbm5lckV4Y2VwdGlvbiBpbiBleC5Jbm5lckV4Y2VwdGlvbnMpCiAgICAgICAgewogICAgICAgICAgICBDb25zb2xlLldyaXRlTGluZSgkIkNhdWdodCBhbiBleGNlcHRpb246IHtpbm5lckV4Y2VwdGlvbi5NZXNzYWdlfSIpOwogICAgICAgIH0KICAgIH0KfQ=="))));alert("¡Copiado!");return false;'><i class='bi bi-copy'></i></a><pre class='code'>public async Task RunMultipleTasksAsync()
{
    var task1 = Task.Run(() =&gt; { throw new InvalidOperationException(&quot;Task1 failed.&quot;); });
    var task2 = Task.Run(() =&gt; { throw new InvalidOperationException(&quot;Task2 failed.&quot;); });

    try
    {
        await Task.WhenAll(task1, task2);
    }
    catch (Exception ex)
    {
        foreach (var innerException in ex.InnerExceptions)
        {
            Console.WriteLine($&quot;Caught an exception: {innerException.Message}&quot;);
        }
    }
}</pre></div><div class='content'><p>En este ejemplo:</p>
<ul>
<li>Se crean dos tareas, ambas lanzan excepciones.</li>
<li><code>Task.WhenAll</code> espera a que ambas tareas se completen.</li>
<li>El bloque <code>catch</code> itera a través de <code>InnerExceptions</code> para manejar cada excepción individualmente.</li>
</ul>
</div><h2>Usando la Propiedad `Task.Exception`</h2>
<div class='content'><p>También puedes acceder a la propiedad <code>Exception</code> de una <code>Task</code> para manejar excepciones después de que la tarea se haya completado.</p>
</div><div style='position:relative'><a class='copy_button' href='#' onclick='navigator.clipboard.writeText(decodeURIComponent(escape(atob("cHVibGljIGFzeW5jIFRhc2sgSGFuZGxlVGFza0V4Y2VwdGlvbkFzeW5jKCkKewogICAgdmFyIHRhc2sgPSBUYXNrLlJ1bigoKSA9PiB7IHRocm93IG5ldyBJbnZhbGlkT3BlcmF0aW9uRXhjZXB0aW9uKCJUYXNrIGZhaWxlZC4iKTsgfSk7CgogICAgdHJ5CiAgICB7CiAgICAgICAgYXdhaXQgdGFzazsKICAgIH0KICAgIGNhdGNoCiAgICB7CiAgICAgICAgaWYgKHRhc2suRXhjZXB0aW9uICE9IG51bGwpCiAgICAgICAgewogICAgICAgICAgICBmb3JlYWNoICh2YXIgaW5uZXJFeGNlcHRpb24gaW4gdGFzay5FeGNlcHRpb24uSW5uZXJFeGNlcHRpb25zKQogICAgICAgICAgICB7CiAgICAgICAgICAgICAgICBDb25zb2xlLldyaXRlTGluZSgkIkNhdWdodCBhbiBleGNlcHRpb246IHtpbm5lckV4Y2VwdGlvbi5NZXNzYWdlfSIpOwogICAgICAgICAgICB9CiAgICAgICAgfQogICAgfQp9"))));alert("¡Copiado!");return false;'><i class='bi bi-copy'></i></a><pre class='code'>public async Task HandleTaskExceptionAsync()
{
    var task = Task.Run(() =&gt; { throw new InvalidOperationException(&quot;Task failed.&quot;); });

    try
    {
        await task;
    }
    catch
    {
        if (task.Exception != null)
        {
            foreach (var innerException in task.Exception.InnerExceptions)
            {
                Console.WriteLine($&quot;Caught an exception: {innerException.Message}&quot;);
            }
        }
    }
}</pre></div><div class='content'><p>En este ejemplo:</p>
<ul>
<li>Se crea una tarea que lanza una excepción.</li>
<li>El bloque <code>catch</code> verifica la propiedad <code>Exception</code> de la tarea y maneja cada excepción interna.</li>
</ul>
</div><h1>Conclusión</h1>
<div class='content'><p>Manejar excepciones en código asíncrono es crucial para construir aplicaciones robustas y confiables. Al entender y aplicar las técnicas discutidas en esta sección, puedes manejar efectivamente los errores en tus métodos asíncronos. Recuerda:</p>
<ul>
<li>Usar bloques <code>try-catch</code> para manejar excepciones en métodos asíncronos.</li>
<li>Propagar excepciones a niveles superiores cuando sea necesario.</li>
<li>Utilizar <code>Task.WhenAll</code> y la propiedad <code>Exception</code> de las tareas para escenarios avanzados de manejo de excepciones.</li>
</ul>
<p>Con estas herramientas y técnicas, estarás bien equipado para manejar excepciones en tu código asíncrono en C#, asegurando que tus aplicaciones funcionen sin problemas incluso cuando ocurran errores inesperados.</p>
</div><div class='row navigation'>
	<div class='col-4'>
					<a href='async-await'>&#x25C4;Async y Await</a>
			</div>
	<div class='col-4 text-center'>
		<a href="./" class="title">Manejo de Excepciones en Código Asíncrono</a>
	</div>
	<div class='col-4 text-end'>
					<a href='introduction-databases'>Introducción a las Bases de Datos &#x25BA;</a>
			</div>
</div>
</div>
		</div>
		<div class="col-12 col-lg-4 publi" id="div_publi">
			<h1>Publicidad</h1>
			<p>Este espacio está destinado a publicidad.</p>
			<p>Si quieres ser patrocinador, contáctanos para incluir enlaces en esta zona: <a href='mailto:admin@campusempresa.cat'>admin@campusempresa.cat</a></p>
			<p>¡Gracias por colaborar!</p>
		</div>
	</div>
</div>

   <div class="container-xxl my-3">
	<div class="row">
		<div class="col">
			<footer>&copy; Copyright 2024. Todos los derechos reservados</footer>
		</div>
	</div>
</div>	

<div id="cookies_adv" style="display:none;">
	Fem servir galetes per millorar la teva experiència d'ús i oferir continguts adaptats als teus interessos
    <a href="#" id="btn_accept_cookies" class="button">Entès!</a>
    <a href="/cookies">Més informació</a>
</div>	

	</div>    
</body>
</html>
