<!DOCTYPE html>
<html lang="es">
<head>
    <meta charset="utf-8">
    <meta http-equiv="x-ua-compatible" content="ie=edge">
    <meta name="viewport" content="width=device-width, initial-scale=1.0">
    <title>Manejo Avanzado de Errores</title>

    <link rel="alternate" href="https://campusempresa.com/mod/swift/05-02-advanced-error-handling" hreflang="es" />
	<link rel="alternate" href="https://campusempresa.cat/mod/swift/05-02-advanced-error-handling" hreflang="ca" />
	<link rel="alternate" href="https://enterprisecampus.net/mod/swift/05-02-advanced-error-handling" hreflang="en" />
    
	<link href="https://cdn.jsdelivr.net/npm/bootstrap@5.3.3/dist/css/bootstrap.min.css" rel="stylesheet">
	<link rel="stylesheet" href="https://cdn.jsdelivr.net/npm/bootstrap-icons/font/bootstrap-icons.css">
	<link href="/css/site.css" rel="stylesheet">
	
    <script src="https://code.jquery.com/jquery-3.7.1.min.js"></script>
  	<script type="text/javascript" src="/js/math_init.js"></script>
  	<script type="text/javascript" id="MathJax-script" src="https://cdn.jsdelivr.net/npm/mathjax@3/es5/startup.js"></script>
  	<script type="text/javascript" src="/js/cookie.js"></script>
  	<script type="text/javascript" src="/js/main.js"></script>
</head>

<body >
    <div id="content">
		<div id="header" class="container-xxl">
	<div class="row">
		<div class="col-12 col-md-8 p-2 p-md-0">
			<h1 class="m-0 p-0">
				<a href="/"><img src="/img/logo_header.png"></a>
			</h1>
		</div>
		<div class="col-12 col-md-4 p-2 p-md-0 text-end">
			<h2 id="main_title"><cite>Construyendo la sociedad de hoy y del mañana</cite></h2>
			<h3 id="main_subtitle"></h3>
		</div>
	</div>
</div>
<div class="container-xxl" style="margin-top: -1em;">
	<div class="row">
		<div class="col-12 p-2 p-md-0 m-0 text-end">
										<a href="https://enterprisecampus.net/mod/swift/05-02-advanced-error-handling" class="px-2">EN</a></b>
				|
				<b class="px-2">ES</b>
				|
				<a href="https://campusempresa.cat/mod/swift/05-02-advanced-error-handling" class="px-2">CA</a>
								</div>
	</div>
</div>
   <div class="top-bar container-fluid">
	<div class="container-xxl">
		<div class="row">
			<div class="col" id="left_menu">
				<a href="/objective">El Proyecto</a>
				<a href="/about">Sobre nosotros</a>
				<a href="/contribute">Contribuir</a>
				<a href="/donate">Donaciones</a>
				<a href="/licence">Licencia</a>
			</div>
		</div>
	</div>
   </div>

<div class="container-xxl" id="main_content">
	<div class="row">
		<div class="col-12 col-lg-8">
			<div id="nav1" class="navigation"></div>
			<div id="inner_content">
								<div class='row navigation'>
	<div class='col-2'>
					<a href='05-01-generics' title="Genéricos">&#x25C4;Anterior</a>
			</div>
	<div class='col-8 text-center'>
					<a href="./"><h2 style="text-decoration:underline">Manejo Avanzado de Errores</h2></a>
			</div>
	<div class='col-2 text-end'>
					<a href='05-03-memory-management' title="Gestión de Memoria">Siguiente &#x25BA;</a>
			</div>
</div>
<div class='content'><p>En este módulo, profundizaremos en el manejo avanzado de errores en Swift. Aprenderemos cómo definir y lanzar errores personalizados, cómo utilizar <code>try?</code> y <code>try!</code>, y cómo trabajar con errores en funciones asíncronas. Este conocimiento es crucial para escribir código robusto y manejable.</p>
</div><h1><p>Contenido</p>
</h1>
<div class='content'><ol>
<li><a href="#definición-de-errores-personalizados">Definición de Errores Personalizados</a></li>
<li><a href="#lanzamiento-y-captura-de-errores">Lanzamiento y Captura de Errores</a></li>
<li><a href="#uso-de-try-y-try">Uso de <code>try?</code> y <code>try!</code></a></li>
<li><a href="#propagación-de-errores">Propagación de Errores</a></li>
<li><a href="#errores-en-funciones-asíncronas">Errores en Funciones Asíncronas</a></li>
<li><a href="#ejercicios-prácticos">Ejercicios Prácticos</a></li>
</ol>
</div><h1><p>Definición de Errores Personalizados</p>
</h1>
<div class='content'><p>En Swift, los errores se definen mediante enumeraciones que adoptan el protocolo <code>Error</code>. Esto permite crear tipos de error personalizados que se pueden lanzar y capturar.</p>
</div><div style='position:relative'><a class='copy_button' href='#' onclick='navigator.clipboard.writeText(decodeURIComponent(escape(atob("ZW51bSBOZXR3b3JrRXJyb3I6IEVycm9yIHsKICAgIGNhc2UgYmFkVVJMCiAgICBjYXNlIHJlcXVlc3RGYWlsZWQKICAgIGNhc2UgdW5rbm93bgp9"))));alert("¡Copiado!");return false;'><i class='bi bi-copy'></i></a><pre class='code'>enum NetworkError: Error {
    case badURL
    case requestFailed
    case unknown
}</pre></div><div class='content'></div><h2><p>Explicación</p>
</h2>
<div class='content'><ul>
<li><code>NetworkError</code> es una enumeración que adopta el protocolo <code>Error</code>.</li>
<li>Cada caso de la enumeración representa un tipo específico de error que puede ocurrir.</li>
</ul>
</div><h1><p>Lanzamiento y Captura de Errores</p>
</h1>
<div class='content'><p>Para lanzar un error, se utiliza la palabra clave <code>throw</code>. Para capturar errores, se utiliza una estructura <code>do-catch</code>.</p>
</div><div style='position:relative'><a class='copy_button' href='#' onclick='navigator.clipboard.writeText(decodeURIComponent(escape(atob("ZnVuYyBmZXRjaERhdGEoZnJvbSB1cmw6IFN0cmluZykgdGhyb3dzIHsKICAgIGd1YXJkIHVybCA9PSAiaHR0cHM6Ly92YWxpZC51cmwiIGVsc2UgewogICAgICAgIHRocm93IE5ldHdvcmtFcnJvci5iYWRVUkwKICAgIH0KICAgIC8vIFNpbXVsYWNpw7NuIGRlIHVuYSBzb2xpY2l0dWQgZGUgcmVkCiAgICBsZXQgc3VjY2VzcyA9IGZhbHNlCiAgICBpZiAhc3VjY2VzcyB7CiAgICAgICAgdGhyb3cgTmV0d29ya0Vycm9yLnJlcXVlc3RGYWlsZWQKICAgIH0KfQoKZG8gewogICAgdHJ5IGZldGNoRGF0YShmcm9tOiAiaHR0cHM6Ly9pbnZhbGlkLnVybCIpCn0gY2F0Y2ggTmV0d29ya0Vycm9yLmJhZFVSTCB7CiAgICBwcmludCgiVVJMIGludsOhbGlkYS4iKQp9IGNhdGNoIE5ldHdvcmtFcnJvci5yZXF1ZXN0RmFpbGVkIHsKICAgIHByaW50KCJMYSBzb2xpY2l0dWQgZmFsbMOzLiIpCn0gY2F0Y2ggewogICAgcHJpbnQoIk9jdXJyacOzIHVuIGVycm9yIGRlc2Nvbm9jaWRvLiIpCn0="))));alert("¡Copiado!");return false;'><i class='bi bi-copy'></i></a><pre class='code'>func fetchData(from url: String) throws {
    guard url == &quot;https://valid.url&quot; else {
        throw NetworkError.badURL
    }
    // Simulaci&oacute;n de una solicitud de red
    let success = false
    if !success {
        throw NetworkError.requestFailed
    }
}

do {
    try fetchData(from: &quot;https://invalid.url&quot;)
} catch NetworkError.badURL {
    print(&quot;URL inv&aacute;lida.&quot;)
} catch NetworkError.requestFailed {
    print(&quot;La solicitud fall&oacute;.&quot;)
} catch {
    print(&quot;Ocurri&oacute; un error desconocido.&quot;)
}</pre></div><div class='content'></div><h2><p>Explicación</p>
</h2>
<div class='content'><ul>
<li><code>fetchData(from:)</code> es una función que puede lanzar errores (<code>throws</code>).</li>
<li>Se utiliza <code>guard</code> para verificar la validez de la URL y lanzar un error si es inválida.</li>
<li>En el bloque <code>do</code>, se intenta ejecutar <code>fetchData(from:)</code> y se capturan los errores específicos en los bloques <code>catch</code>.</li>
</ul>
</div><h1><p>Uso de <code>try?</code> y <code>try!</code></p>
</h1>
<div class='content'><p>Swift proporciona dos formas adicionales de manejar errores: <code>try?</code> y <code>try!</code>.</p>
</div><h2><p><code>try?</code></p>
</h2>
<div class='content'><p>Convierte el resultado en un valor opcional. Si la función lanza un error, el resultado será <code>nil</code>.</p>
</div><div style='position:relative'><a class='copy_button' href='#' onclick='navigator.clipboard.writeText(decodeURIComponent(escape(atob("bGV0IGRhdGEgPSB0cnk/IGZldGNoRGF0YShmcm9tOiAiaHR0cHM6Ly9pbnZhbGlkLnVybCIpCmlmIGRhdGEgPT0gbmlsIHsKICAgIHByaW50KCJFcnJvciBhbCBvYnRlbmVyIGxvcyBkYXRvcy4iKQp9"))));alert("¡Copiado!");return false;'><i class='bi bi-copy'></i></a><pre class='code'>let data = try? fetchData(from: &quot;https://invalid.url&quot;)
if data == nil {
    print(&quot;Error al obtener los datos.&quot;)
}</pre></div><div class='content'></div><h2><p><code>try!</code></p>
</h2>
<div class='content'><p>Asume que la función no lanzará un error. Si lo hace, el programa se detendrá.</p>
</div><div style='position:relative'><a class='copy_button' href='#' onclick='navigator.clipboard.writeText(decodeURIComponent(escape(atob("bGV0IGRhdGEgPSB0cnkhIGZldGNoRGF0YShmcm9tOiAiaHR0cHM6Ly92YWxpZC51cmwiKQpwcmludCgiRGF0b3Mgb2J0ZW5pZG9zIGNvbiDDqXhpdG8uIik="))));alert("¡Copiado!");return false;'><i class='bi bi-copy'></i></a><pre class='code'>let data = try! fetchData(from: &quot;https://valid.url&quot;)
print(&quot;Datos obtenidos con &eacute;xito.&quot;)</pre></div><div class='content'></div><h2><p>Explicación</p>
</h2>
<div class='content'><ul>
<li><code>try?</code> es útil cuando no te importa el error específico y solo necesitas saber si la operación tuvo éxito.</li>
<li><code>try!</code> debe usarse con precaución, ya que puede causar que el programa se detenga si se lanza un error.</li>
</ul>
</div><h1><p>Propagación de Errores</p>
</h1>
<div class='content'><p>Los errores pueden propagarse a través de múltiples niveles de funciones. Esto se hace declarando que una función puede lanzar errores (<code>throws</code>) y utilizando <code>try</code> al llamar a otras funciones que también pueden lanzar errores.</p>
</div><div style='position:relative'><a class='copy_button' href='#' onclick='navigator.clipboard.writeText(decodeURIComponent(escape(atob("ZnVuYyBwZXJmb3JtTmV0d29ya1JlcXVlc3QoKSB0aHJvd3MgewogICAgdHJ5IGZldGNoRGF0YShmcm9tOiAiaHR0cHM6Ly92YWxpZC51cmwiKQp9CgpkbyB7CiAgICB0cnkgcGVyZm9ybU5ldHdvcmtSZXF1ZXN0KCkKfSBjYXRjaCB7CiAgICBwcmludCgiRXJyb3IgZHVyYW50ZSBsYSBzb2xpY2l0dWQgZGUgcmVkOiBcKGVycm9yKSIpCn0="))));alert("¡Copiado!");return false;'><i class='bi bi-copy'></i></a><pre class='code'>func performNetworkRequest() throws {
    try fetchData(from: &quot;https://valid.url&quot;)
}

do {
    try performNetworkRequest()
} catch {
    print(&quot;Error durante la solicitud de red: \(error)&quot;)
}</pre></div><div class='content'></div><h2><p>Explicación</p>
</h2>
<div class='content'><ul>
<li><code>performNetworkRequest()</code> llama a <code>fetchData(from:)</code> y propaga cualquier error que se lance.</li>
<li>En el bloque <code>do</code>, se captura cualquier error lanzado por <code>performNetworkRequest()</code>.</li>
</ul>
</div><h1><p>Errores en Funciones Asíncronas</p>
</h1>
<div class='content'><p>En Swift, las funciones asíncronas pueden manejar errores utilizando el mismo enfoque de <code>throws</code> y <code>try</code>.</p>
</div><div style='position:relative'><a class='copy_button' href='#' onclick='navigator.clipboard.writeText(decodeURIComponent(escape(atob("ZnVuYyBmZXRjaERhdGFBc3luYyhmcm9tIHVybDogU3RyaW5nLCBjb21wbGV0aW9uOiBAZXNjYXBpbmcgKFJlc3VsdDxTdHJpbmcsIEVycm9yPikgLT4gVm9pZCkgewogICAgRGlzcGF0Y2hRdWV1ZS5nbG9iYWwoKS5hc3luYyB7CiAgICAgICAgZG8gewogICAgICAgICAgICB0cnkgZmV0Y2hEYXRhKGZyb206IHVybCkKICAgICAgICAgICAgY29tcGxldGlvbiguc3VjY2VzcygiRGF0b3Mgb2J0ZW5pZG9zIGNvbiDDqXhpdG8uIikpCiAgICAgICAgfSBjYXRjaCB7CiAgICAgICAgICAgIGNvbXBsZXRpb24oLmZhaWx1cmUoZXJyb3IpKQogICAgICAgIH0KICAgIH0KfQoKZmV0Y2hEYXRhQXN5bmMoZnJvbTogImh0dHBzOi8vaW52YWxpZC51cmwiKSB7IHJlc3VsdCBpbgogICAgc3dpdGNoIHJlc3VsdCB7CiAgICBjYXNlIC5zdWNjZXNzKGxldCBkYXRhKToKICAgICAgICBwcmludChkYXRhKQogICAgY2FzZSAuZmFpbHVyZShsZXQgZXJyb3IpOgogICAgICAgIHByaW50KCJFcnJvcjogXChlcnJvcikiKQogICAgfQp9"))));alert("¡Copiado!");return false;'><i class='bi bi-copy'></i></a><pre class='code'>func fetchDataAsync(from url: String, completion: @escaping (Result&lt;String, Error&gt;) -&gt; Void) {
    DispatchQueue.global().async {
        do {
            try fetchData(from: url)
            completion(.success(&quot;Datos obtenidos con &eacute;xito.&quot;))
        } catch {
            completion(.failure(error))
        }
    }
}

fetchDataAsync(from: &quot;https://invalid.url&quot;) { result in
    switch result {
    case .success(let data):
        print(data)
    case .failure(let error):
        print(&quot;Error: \(error)&quot;)
    }
}</pre></div><div class='content'></div><h2><p>Explicación</p>
</h2>
<div class='content'><ul>
<li><code>fetchDataAsync(from:completion:)</code> es una función asíncrona que utiliza un bloque de finalización (<code>completion</code>) para manejar el resultado.</li>
<li>Utiliza <code>DispatchQueue.global().async</code> para ejecutar la solicitud de red en un hilo de fondo.</li>
<li>El bloque de finalización recibe un <code>Result</code> que puede ser <code>.success</code> o <code>.failure</code>.</li>
</ul>
</div><h1><p>Ejercicios Prácticos</p>
</h1>
<div class='content'></div><h2><p>Ejercicio 1: Definir y Lanzar Errores Personalizados</p>
</h2>
<div class='content'><p>Define una enumeración de errores personalizados para una función que valida direcciones de correo electrónico. Implementa la función y lanza errores apropiados.</p>
</div><div style='position:relative'><a class='copy_button' href='#' onclick='navigator.clipboard.writeText(decodeURIComponent(escape(atob("ZW51bSBFbWFpbEVycm9yOiBFcnJvciB7CiAgICBjYXNlIGludmFsaWRGb3JtYXQKICAgIGNhc2UgZG9tYWluTm90QWxsb3dlZAp9CgpmdW5jIHZhbGlkYXRlRW1haWwoXyBlbWFpbDogU3RyaW5nKSB0aHJvd3MgewogICAgZ3VhcmQgZW1haWwuY29udGFpbnMoIkAiKSBlbHNlIHsKICAgICAgICB0aHJvdyBFbWFpbEVycm9yLmludmFsaWRGb3JtYXQKICAgIH0KICAgIGd1YXJkIGVtYWlsLmhhc1N1ZmZpeCgiQGV4YW1wbGUuY29tIikgZWxzZSB7CiAgICAgICAgdGhyb3cgRW1haWxFcnJvci5kb21haW5Ob3RBbGxvd2VkCiAgICB9Cn0KCmRvIHsKICAgIHRyeSB2YWxpZGF0ZUVtYWlsKCJ1c2VyQGludmFsaWQuY29tIikKfSBjYXRjaCBFbWFpbEVycm9yLmludmFsaWRGb3JtYXQgewogICAgcHJpbnQoIkZvcm1hdG8gZGUgY29ycmVvIGVsZWN0csOzbmljbyBpbnbDoWxpZG8uIikKfSBjYXRjaCBFbWFpbEVycm9yLmRvbWFpbk5vdEFsbG93ZWQgewogICAgcHJpbnQoIkRvbWluaW8gbm8gcGVybWl0aWRvLiIpCn0gY2F0Y2ggewogICAgcHJpbnQoIk9jdXJyacOzIHVuIGVycm9yIGRlc2Nvbm9jaWRvLiIpCn0="))));alert("¡Copiado!");return false;'><i class='bi bi-copy'></i></a><pre class='code'>enum EmailError: Error {
    case invalidFormat
    case domainNotAllowed
}

func validateEmail(_ email: String) throws {
    guard email.contains(&quot;@&quot;) else {
        throw EmailError.invalidFormat
    }
    guard email.hasSuffix(&quot;@example.com&quot;) else {
        throw EmailError.domainNotAllowed
    }
}

do {
    try validateEmail(&quot;user@invalid.com&quot;)
} catch EmailError.invalidFormat {
    print(&quot;Formato de correo electr&oacute;nico inv&aacute;lido.&quot;)
} catch EmailError.domainNotAllowed {
    print(&quot;Dominio no permitido.&quot;)
} catch {
    print(&quot;Ocurri&oacute; un error desconocido.&quot;)
}</pre></div><div class='content'></div><h2><p>Ejercicio 2: Uso de <code>try?</code> y <code>try!</code></p>
</h2>
<div class='content'><p>Modifica la función <code>validateEmail</code> para usar <code>try?</code> y <code>try!</code>.</p>
</div><div style='position:relative'><a class='copy_button' href='#' onclick='navigator.clipboard.writeText(decodeURIComponent(escape(atob("bGV0IGVtYWlsVmFsaWRhdGlvbjEgPSB0cnk/IHZhbGlkYXRlRW1haWwoInVzZXJAaW52YWxpZC5jb20iKQppZiBlbWFpbFZhbGlkYXRpb24xID09IG5pbCB7CiAgICBwcmludCgiRXJyb3IgYWwgdmFsaWRhciBlbCBjb3JyZW8gZWxlY3Ryw7NuaWNvLiIpCn0KCmxldCBlbWFpbFZhbGlkYXRpb24yID0gdHJ5ISB2YWxpZGF0ZUVtYWlsKCJ1c2VyQGV4YW1wbGUuY29tIikKcHJpbnQoIkNvcnJlbyBlbGVjdHLDs25pY28gdsOhbGlkby4iKQ=="))));alert("¡Copiado!");return false;'><i class='bi bi-copy'></i></a><pre class='code'>let emailValidation1 = try? validateEmail(&quot;user@invalid.com&quot;)
if emailValidation1 == nil {
    print(&quot;Error al validar el correo electr&oacute;nico.&quot;)
}

let emailValidation2 = try! validateEmail(&quot;user@example.com&quot;)
print(&quot;Correo electr&oacute;nico v&aacute;lido.&quot;)</pre></div><div class='content'></div><h2><p>Ejercicio 3: Propagación de Errores</p>
</h2>
<div class='content'><p>Crea una función que llame a <code>validateEmail</code> y propague cualquier error que se lance.</p>
</div><div style='position:relative'><a class='copy_button' href='#' onclick='navigator.clipboard.writeText(decodeURIComponent(escape(atob("ZnVuYyBjaGVja0VtYWlsKF8gZW1haWw6IFN0cmluZykgdGhyb3dzIHsKICAgIHRyeSB2YWxpZGF0ZUVtYWlsKGVtYWlsKQp9CgpkbyB7CiAgICB0cnkgY2hlY2tFbWFpbCgidXNlckBpbnZhbGlkLmNvbSIpCn0gY2F0Y2ggewogICAgcHJpbnQoIkVycm9yIGFsIHZlcmlmaWNhciBlbCBjb3JyZW8gZWxlY3Ryw7NuaWNvOiBcKGVycm9yKSIpCn0="))));alert("¡Copiado!");return false;'><i class='bi bi-copy'></i></a><pre class='code'>func checkEmail(_ email: String) throws {
    try validateEmail(email)
}

do {
    try checkEmail(&quot;user@invalid.com&quot;)
} catch {
    print(&quot;Error al verificar el correo electr&oacute;nico: \(error)&quot;)
}</pre></div><div class='content'></div><h1><p>Conclusión</p>
</h1>
<div class='content'><p>En esta sección, hemos explorado el manejo avanzado de errores en Swift. Aprendimos a definir y lanzar errores personalizados, utilizar <code>try?</code> y <code>try!</code>, propagar errores y manejar errores en funciones asíncronas. Estos conceptos son fundamentales para escribir código Swift robusto y manejable. En el próximo módulo, profundizaremos en la gestión de memoria en Swift.</p>
</div><div class='row navigation'>
	<div class='col-2'>
					<a href='05-01-generics' title="Genéricos">&#x25C4;Anterior</a>
			</div>
	<div class='col-8 text-center'>
			</div>
	<div class='col-2 text-end'>
					<a href='05-03-memory-management' title="Gestión de Memoria">Siguiente &#x25BA;</a>
			</div>
</div>

			</div>
		</div>
		<div class="col-12 col-lg-4 publi" id="div_publi">
			<h1>Publicidad</h1>
			<p>Este espacio está destinado a publicidad.</p>
			<p>Si quieres ser patrocinador, contáctanos para incluir enlaces en esta zona: <a href='mailto:admin@campusempresa.cat'>admin@campusempresa.cat</a></p>
			<p>¡Gracias por colaborar!</p>
		</div>
	</div>
</div>

   <div class="container-xxl my-3">
	<div class="row">
		<div class="col">
			<footer>&copy; Copyright 2024. Todos los derechos reservados</footer>
		</div>
	</div>
</div>	

<div id="cookies_adv" style="display:none;">
	Fem servir galetes per millorar la teva experiència d'ús i oferir continguts adaptats als teus interessos
    <a href="#" id="btn_accept_cookies" class="button">Aceptar</a>
    <a href="/cookies">Mas información</a>
</div>	

	</div>    
</body>
</html>
